<?xml version="1.0" encoding="utf-8"?>
<!-- This URDF was automatically created by SolidWorks to URDF Exporter! Originally created by Stephen Brawner (brawner@gmail.com) 
     Commit Version: 1.6.0-1-g15f4949  Build Version: 1.6.7594.29634
     For more information, please see http://wiki.ros.org/sw_urdf_exporter -->
<robot
  name="eva">
  <link
    name="evaBot01_base">
    <inertial>
      <origin
        xyz="-0.037166 -0.0044862 0.066632"
        rpy="0 0 0" />
      <mass
        value="2.604" />
      <inertia
        ixx="0.0035998"
        ixy="-1.1358E-05"
        ixz="-2.3646E-05"
        iyy="0.004967"
        iyz="8.6177E-07"
        izz="0.006078" />
    </inertial>
    <visual>
      <origin
        xyz="0 0 0"
        rpy="0 0 0" />
      <geometry>
        <mesh
          filename="package://eva/meshes/evaBot01_base.STL" />
      </geometry>
      <material
        name="">
        <color
          rgba="1 1 1 1" />
      </material>
    </visual>
    <collision>
      <origin
        xyz="0 0 0"
        rpy="0 0 0" />
      <geometry>
        <mesh
          filename="package://eva/meshes/evaBot01_base.STL" />
      </geometry>
    </collision>
  </link>
  <link
    name="evaBot01_left_wheel">
    <inertial>
      <origin
        xyz="0.11732 -0.19696 2.0333E-08"
        rpy="0 0 0" />
      <mass
        value="0.055895" />
      <inertia
        ixx="1.0957E-05"
        ixy="-2.5639E-06"
        ixz="-5.9397E-12"
        iyy="7.9962E-06"
        iyz="-5.248E-12"
        izz="6.516E-06" />
    </inertial>
    <visual>
      <origin
        xyz="0 0 0"
        rpy="0 0 0" />
      <geometry>
        <mesh
          filename="package://eva/meshes/evaBot01_back_wheel.STL" />
      </geometry>
      <material
        name="">
        <color
          rgba="1 1 1 1" />
      </material>
    </visual>
    <collision>
      <origin
        xyz="0 0 0"
        rpy="0 0 0" />
      <geometry>
        <mesh
          filename="package://eva/meshes/evaBot01_back_wheel.STL" />
      </geometry>
    </collision>
  </link>
  <joint
    name="left_wheel_to_base"
    type="continuous">
    <origin
      xyz="0.06461 0.11191 0.019"
      rpy="0 0 -0.5236" />
    <parent
      link="evaBot01_base" />
    <child
      link="evaBot01_left_wheel" />
    <axis
      xyz="0 -1 0" />
  </joint>
  <link
    name="evaBot01_right_wheel">
    <inertial>
      <origin
        xyz="0.11732 0.19696 -3.424E-09"
        rpy="0 0 0" />
      <mass
        value="0.055895" />
      <inertia
        ixx="1.0957E-05"
        ixy="2.5639E-06"
        ixz="9.1144E-12"
        iyy="7.9963E-06"
        iyz="-1.0797E-11"
        izz="6.516E-06" />
    </inertial>
    <visual>
      <origin
        xyz="0 0 0"
        rpy="0 0 0" />
      <geometry>
        <mesh
          filename="package://eva/meshes/evaBot01_back_wheel.STL" />
      </geometry>
      <material
        name="">
        <color
          rgba="0.89804 0.91765 0.92941 1" />
      </material>
    </visual>
    <collision>
      <origin
        xyz="0 0 0"
        rpy="0 0 0" />
      <geometry>
        <mesh
          filename="package://eva/meshes/evaBot01_back_wheel.STL" />
      </geometry>
    </collision>
  </link>
  <joint
    name="right_wheel_to_base"
    type="continuous">
    <origin
      xyz="0.06461 -0.11191 0.019"
      rpy="0 0 0.5236" />
    <parent
      link="evaBot01_base" />
    <child
      link="evaBot01_right_wheel" />
    <axis
      xyz="0 1 0" />
  </joint>
  <link
    name="evaBot01_back_wheel">
    <inertial>
      <origin
        xyz="0.11732 0.19696 -3.424E-09"
        rpy="0 0 0" />
      <mass
        value="0.055895" />
      <inertia
        ixx="1.0957E-05"
        ixy="2.5639E-06"
        ixz="9.1144E-12"
        iyy="7.9963E-06"
        iyz="-1.0797E-11"
        izz="6.516E-06" />
    </inertial>
    <visual>
      <origin
        xyz="0 0 0"
        rpy="0 0 0" />
      <geometry>
        <mesh
          filename="package://eva/meshes/evaBot01_back_wheel.STL" />
      </geometry>
      <material
        name="">
        <color
          rgba="1 1 1 1" />
      </material>
    </visual>
    <collision>
      <origin
        xyz="0 0 0"
        rpy="0 0 0" />
      <geometry>
        <mesh
          filename="package://eva/meshes/evaBot01_back_wheel.STL" />
      </geometry>
    </collision>
  </link>
  <joint
    name="back_wheel_to_base"
    type="continuous">
    <origin
      xyz="-0.129220573348487 0 0.0190000000000005"
      rpy="0 0 -1.57079632679484" />
    <parent
      link="evaBot01_base" />
    <child
      link="evaBot01_back_wheel" />
    <axis
      xyz="0 1 0" />
  </joint>
</robot>